[26/Nov/2020 13:30:56] "GET / HTTP/1.1" 200 3608
[26/Nov/2020 13:30:57] "GET / HTTP/1.1" 200 3608
[26/Nov/2020 13:32:11] "GET / HTTP/1.1" 200 3608
[26/Nov/2020 13:32:11] "GET / HTTP/1.1" 200 3608
[26/Nov/2020 13:32:12] "GET /favicon.ico HTTP/1.1" 500 4061
[26/Nov/2020 13:32:40] "GET / HTTP/1.1" 200 3608
[26/Nov/2020 13:32:41] "GET / HTTP/1.1" 200 3608
[26/Nov/2020 13:32:46] "GET / HTTP/1.1" 200 3608
[26/Nov/2020 13:32:53] "POST /tj HTTP/1.1" 200 831
[26/Nov/2020 13:32:53] "GET /favicon.ico HTTP/1.1" 500 4061
[26/Nov/2020 13:32:54] "GET / HTTP/1.1" 200 3558
[26/Nov/2020 13:32:55] "GET / HTTP/1.1" 200 3558
[26/Nov/2020 13:33:41] "GET /tj HTTP/1.1" 200 849
[26/Nov/2020 13:33:44] "GET /tj HTTP/1.1" 200 849
[26/Nov/2020 13:34:13] "GET / HTTP/1.1" 200 3558
[26/Nov/2020 13:34:14] "GET / HTTP/1.1" 200 3558
[26/Nov/2020 13:34:48] "GET /favicon.ico HTTP/1.1" 500 4061
[26/Nov/2020 13:35:23] "GET / HTTP/1.1" 200 3558
[26/Nov/2020 13:35:24] "GET / HTTP/1.1" 200 3558
[26/Nov/2020 13:35:48] "GET /favicon.ico HTTP/1.1" 500 4061
[26/Nov/2020 13:36:03] "GET / HTTP/1.1" 200 3558
[26/Nov/2020 13:36:56] "GET /favicon.ico HTTP/1.1" 500 4061
[26/Nov/2020 13:37:01] "GET / HTTP/1.1" 200 3558
[26/Nov/2020 13:37:05] "GET /favicon.ico HTTP/1.1" 500 4061
[26/Nov/2020 13:41:22] "GET / HTTP/1.1" 200 3558
[26/Nov/2020 13:42:42] "GET / HTTP/1.1" 200 3558
[26/Nov/2020 13:42:44] "GET / HTTP/1.1" 200 3558
[26/Nov/2020 13:44:07] "GET / HTTP/1.1" 200 3558
[26/Nov/2020 13:44:09] "GET / HTTP/1.1" 200 3558
[26/Nov/2020 13:45:25] "POST /tj HTTP/1.1" 200 831
[26/Nov/2020 13:45:32] "GET / HTTP/1.1" 200 3511
[26/Nov/2020 13:45:33] "GET / HTTP/1.1" 200 3511
[26/Nov/2020 17:41:31] "GET / HTTP/1.1" 200 3511
[26/Nov/2020 17:41:32] "GET / HTTP/1.1" 200 3511
[26/Nov/2020 23:03:28] "GET /tj HTTP/1.1" 200 849
[26/Nov/2020 23:03:28] "GET /tj HTTP/1.1" 200 849
[26/Nov/2020 23:41:01] "GET / HTTP/1.1" 200 3511
[26/Nov/2020 23:41:02] "GET / HTTP/1.1" 200 3511
[26/Nov/2020 23:41:03] "GET / HTTP/1.1" 200 3511
[27/Nov/2020 00:03:05] "GET / HTTP/1.1" 200 3511
[27/Nov/2020 00:03:06] "GET / HTTP/1.1" 200 3511
[27/Nov/2020 00:03:10] "GET / HTTP/1.1" 200 3511
[27/Nov/2020 00:05:58] "GET / HTTP/1.1" 200 3511
[27/Nov/2020 00:06:01] "GET /tj HTTP/1.1" 200 849
[27/Nov/2020 00:06:01] "POST /tj HTTP/1.1" 200 849
[27/Nov/2020 00:07:31] "GET / HTTP/1.1" 200 3511
[27/Nov/2020 00:09:03] "GET / HTTP/1.1" 200 3511
[27/Nov/2020 00:10:35] "GET / HTTP/1.1" 200 3511
[27/Nov/2020 00:10:42] "POST /tj HTTP/1.1" 200 952
[27/Nov/2020 00:10:44] "POST /tj HTTP/1.1" 200 831
[27/Nov/2020 00:10:45] "GET /favicon.ico HTTP/1.1" 500 4061
[27/Nov/2020 00:10:46] "GET / HTTP/1.1" 200 3464
[27/Nov/2020 00:10:47] "GET / HTTP/1.1" 200 3464
[27/Nov/2020 00:10:49] "GET / HTTP/1.1" 200 3464
[27/Nov/2020 00:10:49] "GET / HTTP/1.1" 200 3464
[27/Nov/2020 00:10:58] "POST /tj HTTP/1.1" 200 952
[27/Nov/2020 00:11:10] "POST /tj HTTP/1.1" 200 952
[27/Nov/2020 00:11:18] "GET / HTTP/1.1" 200 3464
[27/Nov/2020 00:28:12] "GET / HTTP/1.1" 200 3464
[27/Nov/2020 00:28:13] "GET / HTTP/1.1" 200 3464
[27/Nov/2020 00:28:50] "POST /tj HTTP/1.1" 200 831
[27/Nov/2020 00:28:51] "POST /tj HTTP/1.1" 200 952
[27/Nov/2020 00:28:52] "GET /favicon.ico HTTP/1.1" 500 4061
[27/Nov/2020 00:28:58] "GET / HTTP/1.1" 200 3414
[27/Nov/2020 00:28:58] "GET / HTTP/1.1" 200 3414
[27/Nov/2020 00:34:49] "GET / HTTP/1.1" 200 3414
[27/Nov/2020 00:34:49] "GET / HTTP/1.1" 200 3414
[27/Nov/2020 00:43:43] "POST /tj HTTP/1.1" 200 831
[27/Nov/2020 00:43:44] "GET /favicon.ico HTTP/1.1" 500 4061
[27/Nov/2020 00:43:45] "GET / HTTP/1.1" 200 3364
[27/Nov/2020 00:43:48] "GET / HTTP/1.1" 200 3364
[27/Nov/2020 00:43:48] "GET / HTTP/1.1" 200 3364
[27/Nov/2020 01:08:46] "GET / HTTP/1.1" 200 3364
[27/Nov/2020 01:08:46] "GET / HTTP/1.1" 200 3364
[27/Nov/2020 01:09:06] "GET /qingshurumima/ HTTP/1.1" 200 2906
[27/Nov/2020 01:09:07] "GET /qingshurumima/ HTTP/1.1" 200 2906
[27/Nov/2020 01:09:08] "POST /jszy HTTP/1.1" 200 885
[27/Nov/2020 01:09:08] "GET /favicon.ico HTTP/1.1" 500 4061
[27/Nov/2020 01:09:09] "GET /qingshurumima/ HTTP/1.1" 200 2905
[27/Nov/2020 01:09:17] "GET / HTTP/1.1" 200 855
[27/Nov/2020 01:09:18] "GET /favicon.ico HTTP/1.1" 500 4061
Performing system checks...

System check identified no issues (0 silenced).

You have 18 unapplied migration(s). Your project may not work properly until you apply the migrations for app(s): admin, auth, contenttypes, sessions.
Run 'python manage.py migrate' to apply them.
November 26, 2020 - 13:30:53
Django version 3.1.3, using settings 'receivefiles.settings'
Starting development server at http://0.0.0.0:2580/
Quit the server with CONTROL-C.
Exception in thread django-main-thread:
Traceback (most recent call last):
  File "/usr/lib/python3.6/threading.py", line 916, in _bootstrap_inner
    self.run()
  File "/usr/lib/python3.6/threading.py", line 864, in run
    self._target(*self._args, **self._kwargs)
  File "/usr/local/lib/python3.6/dist-packages/django/utils/autoreload.py", line 53, in wrapper
    fn(*args, **kwargs)
  File "/usr/local/lib/python3.6/dist-packages/django/core/management/commands/runserver.py", line 118, in inner_run
    self.check(display_num_errors=True)
  File "/usr/local/lib/python3.6/dist-packages/django/core/management/base.py", line 396, in check
    databases=databases,
  File "/usr/local/lib/python3.6/dist-packages/django/core/checks/registry.py", line 70, in run_checks
    new_errors = check(app_configs=app_configs, databases=databases)
  File "/usr/local/lib/python3.6/dist-packages/django/core/checks/urls.py", line 40, in check_url_namespaces_unique
    all_namespaces = _load_all_namespaces(resolver)
  File "/usr/local/lib/python3.6/dist-packages/django/core/checks/urls.py", line 57, in _load_all_namespaces
    url_patterns = getattr(resolver, 'url_patterns', [])
  File "/usr/local/lib/python3.6/dist-packages/django/utils/functional.py", line 48, in __get__
    res = instance.__dict__[self.name] = self.func(instance)
  File "/usr/local/lib/python3.6/dist-packages/django/urls/resolvers.py", line 589, in url_patterns
    patterns = getattr(self.urlconf_module, "urlpatterns", self.urlconf_module)
  File "/usr/local/lib/python3.6/dist-packages/django/utils/functional.py", line 48, in __get__
    res = instance.__dict__[self.name] = self.func(instance)
  File "/usr/local/lib/python3.6/dist-packages/django/urls/resolvers.py", line 582, in urlconf_module
    return import_module(self.urlconf_name)
  File "/usr/lib/python3.6/importlib/__init__.py", line 126, in import_module
    return _bootstrap._gcd_import(name[level:], package, level)
  File "<frozen importlib._bootstrap>", line 994, in _gcd_import
  File "<frozen importlib._bootstrap>", line 971, in _find_and_load
  File "<frozen importlib._bootstrap>", line 955, in _find_and_load_unlocked
  File "<frozen importlib._bootstrap>", line 665, in _load_unlocked
  File "<frozen importlib._bootstrap_external>", line 678, in exec_module
  File "<frozen importlib._bootstrap>", line 219, in _call_with_frames_removed
  File "/etc/django/receivefiles/receivefiles/urls.py", line 19, in <module>
    from . import views
  File "/etc/django/receivefiles/receivefiles/views.py", line 137
    return render(request, 'back.html', context=)
                                                ^
SyntaxError: invalid syntax

Performing system checks...

Exception in thread django-main-thread:
Traceback (most recent call last):
  File "/usr/lib/python3.6/threading.py", line 916, in _bootstrap_inner
    self.run()
  File "/usr/lib/python3.6/threading.py", line 864, in run
    self._target(*self._args, **self._kwargs)
  File "/usr/local/lib/python3.6/dist-packages/django/utils/autoreload.py", line 53, in wrapper
    fn(*args, **kwargs)
  File "/usr/local/lib/python3.6/dist-packages/django/core/management/commands/runserver.py", line 118, in inner_run
    self.check(display_num_errors=True)
  File "/usr/local/lib/python3.6/dist-packages/django/core/management/base.py", line 396, in check
    databases=databases,
  File "/usr/local/lib/python3.6/dist-packages/django/core/checks/registry.py", line 70, in run_checks
    new_errors = check(app_configs=app_configs, databases=databases)
  File "/usr/local/lib/python3.6/dist-packages/django/core/checks/urls.py", line 40, in check_url_namespaces_unique
    all_namespaces = _load_all_namespaces(resolver)
  File "/usr/local/lib/python3.6/dist-packages/django/core/checks/urls.py", line 57, in _load_all_namespaces
    url_patterns = getattr(resolver, 'url_patterns', [])
  File "/usr/local/lib/python3.6/dist-packages/django/utils/functional.py", line 48, in __get__
    res = instance.__dict__[self.name] = self.func(instance)
  File "/usr/local/lib/python3.6/dist-packages/django/urls/resolvers.py", line 589, in url_patterns
    patterns = getattr(self.urlconf_module, "urlpatterns", self.urlconf_module)
  File "/usr/local/lib/python3.6/dist-packages/django/utils/functional.py", line 48, in __get__
    res = instance.__dict__[self.name] = self.func(instance)
  File "/usr/local/lib/python3.6/dist-packages/django/urls/resolvers.py", line 582, in urlconf_module
    return import_module(self.urlconf_name)
  File "/usr/lib/python3.6/importlib/__init__.py", line 126, in import_module
    return _bootstrap._gcd_import(name[level:], package, level)
  File "<frozen importlib._bootstrap>", line 994, in _gcd_import
  File "<frozen importlib._bootstrap>", line 971, in _find_and_load
  File "<frozen importlib._bootstrap>", line 955, in _find_and_load_unlocked
  File "<frozen importlib._bootstrap>", line 665, in _load_unlocked
  File "<frozen importlib._bootstrap_external>", line 678, in exec_module
  File "<frozen importlib._bootstrap>", line 219, in _call_with_frames_removed
  File "/etc/django/receivefiles/receivefiles/urls.py", line 19, in <module>
    from . import views
  File "/etc/django/receivefiles/receivefiles/views.py", line 141
    return render(request, 'back.html', context=)
                                                ^
SyntaxError: invalid syntax

Performing system checks...

Exception in thread django-main-thread:
Traceback (most recent call last):
  File "/usr/lib/python3.6/threading.py", line 916, in _bootstrap_inner
    self.run()
  File "/usr/lib/python3.6/threading.py", line 864, in run
    self._target(*self._args, **self._kwargs)
  File "/usr/local/lib/python3.6/dist-packages/django/utils/autoreload.py", line 53, in wrapper
    fn(*args, **kwargs)
  File "/usr/local/lib/python3.6/dist-packages/django/core/management/commands/runserver.py", line 118, in inner_run
    self.check(display_num_errors=True)
  File "/usr/local/lib/python3.6/dist-packages/django/core/management/base.py", line 396, in check
    databases=databases,
  File "/usr/local/lib/python3.6/dist-packages/django/core/checks/registry.py", line 70, in run_checks
    new_errors = check(app_configs=app_configs, databases=databases)
  File "/usr/local/lib/python3.6/dist-packages/django/core/checks/urls.py", line 40, in check_url_namespaces_unique
    all_namespaces = _load_all_namespaces(resolver)
  File "/usr/local/lib/python3.6/dist-packages/django/core/checks/urls.py", line 57, in _load_all_namespaces
    url_patterns = getattr(resolver, 'url_patterns', [])
  File "/usr/local/lib/python3.6/dist-packages/django/utils/functional.py", line 48, in __get__
    res = instance.__dict__[self.name] = self.func(instance)
  File "/usr/local/lib/python3.6/dist-packages/django/urls/resolvers.py", line 589, in url_patterns
    patterns = getattr(self.urlconf_module, "urlpatterns", self.urlconf_module)
  File "/usr/local/lib/python3.6/dist-packages/django/utils/functional.py", line 48, in __get__
    res = instance.__dict__[self.name] = self.func(instance)
  File "/usr/local/lib/python3.6/dist-packages/django/urls/resolvers.py", line 582, in urlconf_module
    return import_module(self.urlconf_name)
  File "/usr/lib/python3.6/importlib/__init__.py", line 126, in import_module
    return _bootstrap._gcd_import(name[level:], package, level)
  File "<frozen importlib._bootstrap>", line 994, in _gcd_import
  File "<frozen importlib._bootstrap>", line 971, in _find_and_load
  File "<frozen importlib._bootstrap>", line 955, in _find_and_load_unlocked
  File "<frozen importlib._bootstrap>", line 665, in _load_unlocked
  File "<frozen importlib._bootstrap_external>", line 678, in exec_module
  File "<frozen importlib._bootstrap>", line 219, in _call_with_frames_removed
  File "/etc/django/receivefiles/receivefiles/urls.py", line 19, in <module>
    from . import views
  File "/etc/django/receivefiles/receivefiles/views.py", line 141
    return render(request, 'back.html', context=)
                                                ^
SyntaxError: invalid syntax

Performing system checks...

Exception in thread django-main-thread:
Traceback (most recent call last):
  File "/usr/lib/python3.6/threading.py", line 916, in _bootstrap_inner
    self.run()
  File "/usr/lib/python3.6/threading.py", line 864, in run
    self._target(*self._args, **self._kwargs)
  File "/usr/local/lib/python3.6/dist-packages/django/utils/autoreload.py", line 53, in wrapper
    fn(*args, **kwargs)
  File "/usr/local/lib/python3.6/dist-packages/django/core/management/commands/runserver.py", line 118, in inner_run
    self.check(display_num_errors=True)
  File "/usr/local/lib/python3.6/dist-packages/django/core/management/base.py", line 396, in check
    databases=databases,
  File "/usr/local/lib/python3.6/dist-packages/django/core/checks/registry.py", line 70, in run_checks
    new_errors = check(app_configs=app_configs, databases=databases)
  File "/usr/local/lib/python3.6/dist-packages/django/core/checks/urls.py", line 40, in check_url_namespaces_unique
    all_namespaces = _load_all_namespaces(resolver)
  File "/usr/local/lib/python3.6/dist-packages/django/core/checks/urls.py", line 57, in _load_all_namespaces
    url_patterns = getattr(resolver, 'url_patterns', [])
  File "/usr/local/lib/python3.6/dist-packages/django/utils/functional.py", line 48, in __get__
    res = instance.__dict__[self.name] = self.func(instance)
  File "/usr/local/lib/python3.6/dist-packages/django/urls/resolvers.py", line 589, in url_patterns
    patterns = getattr(self.urlconf_module, "urlpatterns", self.urlconf_module)
  File "/usr/local/lib/python3.6/dist-packages/django/utils/functional.py", line 48, in __get__
    res = instance.__dict__[self.name] = self.func(instance)
  File "/usr/local/lib/python3.6/dist-packages/django/urls/resolvers.py", line 582, in urlconf_module
    return import_module(self.urlconf_name)
  File "/usr/lib/python3.6/importlib/__init__.py", line 126, in import_module
    return _bootstrap._gcd_import(name[level:], package, level)
  File "<frozen importlib._bootstrap>", line 994, in _gcd_import
  File "<frozen importlib._bootstrap>", line 971, in _find_and_load
  File "<frozen importlib._bootstrap>", line 955, in _find_and_load_unlocked
  File "<frozen importlib._bootstrap>", line 665, in _load_unlocked
  File "<frozen importlib._bootstrap_external>", line 678, in exec_module
  File "<frozen importlib._bootstrap>", line 219, in _call_with_frames_removed
  File "/etc/django/receivefiles/receivefiles/urls.py", line 19, in <module>
    from . import views
  File "/etc/django/receivefiles/receivefiles/views.py", line 135
    return render(request, 'back.html', context=)
                                                ^
SyntaxError: invalid syntax

Performing system checks...

Exception in thread django-main-thread:
Traceback (most recent call last):
  File "/usr/lib/python3.6/threading.py", line 916, in _bootstrap_inner
    self.run()
  File "/usr/lib/python3.6/threading.py", line 864, in run
    self._target(*self._args, **self._kwargs)
  File "/usr/local/lib/python3.6/dist-packages/django/utils/autoreload.py", line 53, in wrapper
    fn(*args, **kwargs)
  File "/usr/local/lib/python3.6/dist-packages/django/core/management/commands/runserver.py", line 118, in inner_run
    self.check(display_num_errors=True)
  File "/usr/local/lib/python3.6/dist-packages/django/core/management/base.py", line 396, in check
    databases=databases,
  File "/usr/local/lib/python3.6/dist-packages/django/core/checks/registry.py", line 70, in run_checks
    new_errors = check(app_configs=app_configs, databases=databases)
  File "/usr/local/lib/python3.6/dist-packages/django/core/checks/urls.py", line 40, in check_url_namespaces_unique
    all_namespaces = _load_all_namespaces(resolver)
  File "/usr/local/lib/python3.6/dist-packages/django/core/checks/urls.py", line 57, in _load_all_namespaces
    url_patterns = getattr(resolver, 'url_patterns', [])
  File "/usr/local/lib/python3.6/dist-packages/django/utils/functional.py", line 48, in __get__
    res = instance.__dict__[self.name] = self.func(instance)
  File "/usr/local/lib/python3.6/dist-packages/django/urls/resolvers.py", line 589, in url_patterns
    patterns = getattr(self.urlconf_module, "urlpatterns", self.urlconf_module)
  File "/usr/local/lib/python3.6/dist-packages/django/utils/functional.py", line 48, in __get__
    res = instance.__dict__[self.name] = self.func(instance)
  File "/usr/local/lib/python3.6/dist-packages/django/urls/resolvers.py", line 582, in urlconf_module
    return import_module(self.urlconf_name)
  File "/usr/lib/python3.6/importlib/__init__.py", line 126, in import_module
    return _bootstrap._gcd_import(name[level:], package, level)
  File "<frozen importlib._bootstrap>", line 994, in _gcd_import
  File "<frozen importlib._bootstrap>", line 971, in _find_and_load
  File "<frozen importlib._bootstrap>", line 955, in _find_and_load_unlocked
  File "<frozen importlib._bootstrap>", line 665, in _load_unlocked
  File "<frozen importlib._bootstrap_external>", line 678, in exec_module
  File "<frozen importlib._bootstrap>", line 219, in _call_with_frames_removed
  File "/etc/django/receivefiles/receivefiles/urls.py", line 19, in <module>
    from . import views
  File "/etc/django/receivefiles/receivefiles/views.py", line 137
    return render(request, 'back.html', context=)
                                                ^
SyntaxError: invalid syntax

Performing system checks...

Exception in thread django-main-thread:
Traceback (most recent call last):
  File "/usr/lib/python3.6/threading.py", line 916, in _bootstrap_inner
    self.run()
  File "/usr/lib/python3.6/threading.py", line 864, in run
    self._target(*self._args, **self._kwargs)
  File "/usr/local/lib/python3.6/dist-packages/django/utils/autoreload.py", line 53, in wrapper
    fn(*args, **kwargs)
  File "/usr/local/lib/python3.6/dist-packages/django/core/management/commands/runserver.py", line 118, in inner_run
    self.check(display_num_errors=True)
  File "/usr/local/lib/python3.6/dist-packages/django/core/management/base.py", line 396, in check
    databases=databases,
  File "/usr/local/lib/python3.6/dist-packages/django/core/checks/registry.py", line 70, in run_checks
    new_errors = check(app_configs=app_configs, databases=databases)
  File "/usr/local/lib/python3.6/dist-packages/django/core/checks/urls.py", line 40, in check_url_namespaces_unique
    all_namespaces = _load_all_namespaces(resolver)
  File "/usr/local/lib/python3.6/dist-packages/django/core/checks/urls.py", line 57, in _load_all_namespaces
    url_patterns = getattr(resolver, 'url_patterns', [])
  File "/usr/local/lib/python3.6/dist-packages/django/utils/functional.py", line 48, in __get__
    res = instance.__dict__[self.name] = self.func(instance)
  File "/usr/local/lib/python3.6/dist-packages/django/urls/resolvers.py", line 589, in url_patterns
    patterns = getattr(self.urlconf_module, "urlpatterns", self.urlconf_module)
  File "/usr/local/lib/python3.6/dist-packages/django/utils/functional.py", line 48, in __get__
    res = instance.__dict__[self.name] = self.func(instance)
  File "/usr/local/lib/python3.6/dist-packages/django/urls/resolvers.py", line 582, in urlconf_module
    return import_module(self.urlconf_name)
  File "/usr/lib/python3.6/importlib/__init__.py", line 126, in import_module
    return _bootstrap._gcd_import(name[level:], package, level)
  File "<frozen importlib._bootstrap>", line 994, in _gcd_import
  File "<frozen importlib._bootstrap>", line 971, in _find_and_load
  File "<frozen importlib._bootstrap>", line 955, in _find_and_load_unlocked
  File "<frozen importlib._bootstrap>", line 665, in _load_unlocked
  File "<frozen importlib._bootstrap_external>", line 678, in exec_module
  File "<frozen importlib._bootstrap>", line 219, in _call_with_frames_removed
  File "/etc/django/receivefiles/receivefiles/urls.py", line 19, in <module>
    from . import views
  File "/etc/django/receivefiles/receivefiles/views.py", line 137
    return render(request, 'back.html', context=)
                                                ^
SyntaxError: invalid syntax

Performing system checks...

Exception in thread django-main-thread:
Traceback (most recent call last):
  File "/usr/lib/python3.6/threading.py", line 916, in _bootstrap_inner
    self.run()
  File "/usr/lib/python3.6/threading.py", line 864, in run
    self._target(*self._args, **self._kwargs)
  File "/usr/local/lib/python3.6/dist-packages/django/utils/autoreload.py", line 53, in wrapper
    fn(*args, **kwargs)
  File "/usr/local/lib/python3.6/dist-packages/django/core/management/commands/runserver.py", line 118, in inner_run
    self.check(display_num_errors=True)
  File "/usr/local/lib/python3.6/dist-packages/django/core/management/base.py", line 396, in check
    databases=databases,
  File "/usr/local/lib/python3.6/dist-packages/django/core/checks/registry.py", line 70, in run_checks
    new_errors = check(app_configs=app_configs, databases=databases)
  File "/usr/local/lib/python3.6/dist-packages/django/core/checks/urls.py", line 40, in check_url_namespaces_unique
    all_namespaces = _load_all_namespaces(resolver)
  File "/usr/local/lib/python3.6/dist-packages/django/core/checks/urls.py", line 57, in _load_all_namespaces
    url_patterns = getattr(resolver, 'url_patterns', [])
  File "/usr/local/lib/python3.6/dist-packages/django/utils/functional.py", line 48, in __get__
    res = instance.__dict__[self.name] = self.func(instance)
  File "/usr/local/lib/python3.6/dist-packages/django/urls/resolvers.py", line 589, in url_patterns
    patterns = getattr(self.urlconf_module, "urlpatterns", self.urlconf_module)
  File "/usr/local/lib/python3.6/dist-packages/django/utils/functional.py", line 48, in __get__
    res = instance.__dict__[self.name] = self.func(instance)
  File "/usr/local/lib/python3.6/dist-packages/django/urls/resolvers.py", line 582, in urlconf_module
    return import_module(self.urlconf_name)
  File "/usr/lib/python3.6/importlib/__init__.py", line 126, in import_module
    return _bootstrap._gcd_import(name[level:], package, level)
  File "<frozen importlib._bootstrap>", line 994, in _gcd_import
  File "<frozen importlib._bootstrap>", line 971, in _find_and_load
  File "<frozen importlib._bootstrap>", line 955, in _find_and_load_unlocked
  File "<frozen importlib._bootstrap>", line 665, in _load_unlocked
  File "<frozen importlib._bootstrap_external>", line 678, in exec_module
  File "<frozen importlib._bootstrap>", line 219, in _call_with_frames_removed
  File "/etc/django/receivefiles/receivefiles/urls.py", line 19, in <module>
    from . import views
  File "/etc/django/receivefiles/receivefiles/views.py", line 137
    return render(request, 'back.html', context=)
                                                ^
SyntaxError: invalid syntax

Performing system checks...

Exception in thread django-main-thread:
Traceback (most recent call last):
  File "/usr/lib/python3.6/threading.py", line 916, in _bootstrap_inner
    self.run()
  File "/usr/lib/python3.6/threading.py", line 864, in run
    self._target(*self._args, **self._kwargs)
  File "/usr/local/lib/python3.6/dist-packages/django/utils/autoreload.py", line 53, in wrapper
    fn(*args, **kwargs)
  File "/usr/local/lib/python3.6/dist-packages/django/core/management/commands/runserver.py", line 118, in inner_run
    self.check(display_num_errors=True)
  File "/usr/local/lib/python3.6/dist-packages/django/core/management/base.py", line 396, in check
    databases=databases,
  File "/usr/local/lib/python3.6/dist-packages/django/core/checks/registry.py", line 70, in run_checks
    new_errors = check(app_configs=app_configs, databases=databases)
  File "/usr/local/lib/python3.6/dist-packages/django/core/checks/urls.py", line 40, in check_url_namespaces_unique
    all_namespaces = _load_all_namespaces(resolver)
  File "/usr/local/lib/python3.6/dist-packages/django/core/checks/urls.py", line 57, in _load_all_namespaces
    url_patterns = getattr(resolver, 'url_patterns', [])
  File "/usr/local/lib/python3.6/dist-packages/django/utils/functional.py", line 48, in __get__
    res = instance.__dict__[self.name] = self.func(instance)
  File "/usr/local/lib/python3.6/dist-packages/django/urls/resolvers.py", line 589, in url_patterns
    patterns = getattr(self.urlconf_module, "urlpatterns", self.urlconf_module)
  File "/usr/local/lib/python3.6/dist-packages/django/utils/functional.py", line 48, in __get__
    res = instance.__dict__[self.name] = self.func(instance)
  File "/usr/local/lib/python3.6/dist-packages/django/urls/resolvers.py", line 582, in urlconf_module
    return import_module(self.urlconf_name)
  File "/usr/lib/python3.6/importlib/__init__.py", line 126, in import_module
    return _bootstrap._gcd_import(name[level:], package, level)
  File "<frozen importlib._bootstrap>", line 994, in _gcd_import
  File "<frozen importlib._bootstrap>", line 971, in _find_and_load
  File "<frozen importlib._bootstrap>", line 955, in _find_and_load_unlocked
  File "<frozen importlib._bootstrap>", line 665, in _load_unlocked
  File "<frozen importlib._bootstrap_external>", line 678, in exec_module
  File "<frozen importlib._bootstrap>", line 219, in _call_with_frames_removed
  File "/etc/django/receivefiles/receivefiles/urls.py", line 19, in <module>
    from . import views
  File "/etc/django/receivefiles/receivefiles/views.py", line 137
    return render(request, 'back.html', context=)
                                                ^
SyntaxError: invalid syntax

Performing system checks...

Exception in thread django-main-thread:
Traceback (most recent call last):
  File "/usr/lib/python3.6/threading.py", line 916, in _bootstrap_inner
    self.run()
  File "/usr/lib/python3.6/threading.py", line 864, in run
    self._target(*self._args, **self._kwargs)
  File "/usr/local/lib/python3.6/dist-packages/django/utils/autoreload.py", line 53, in wrapper
    fn(*args, **kwargs)
  File "/usr/local/lib/python3.6/dist-packages/django/core/management/commands/runserver.py", line 118, in inner_run
    self.check(display_num_errors=True)
  File "/usr/local/lib/python3.6/dist-packages/django/core/management/base.py", line 396, in check
    databases=databases,
  File "/usr/local/lib/python3.6/dist-packages/django/core/checks/registry.py", line 70, in run_checks
    new_errors = check(app_configs=app_configs, databases=databases)
  File "/usr/local/lib/python3.6/dist-packages/django/core/checks/urls.py", line 40, in check_url_namespaces_unique
    all_namespaces = _load_all_namespaces(resolver)
  File "/usr/local/lib/python3.6/dist-packages/django/core/checks/urls.py", line 57, in _load_all_namespaces
    url_patterns = getattr(resolver, 'url_patterns', [])
  File "/usr/local/lib/python3.6/dist-packages/django/utils/functional.py", line 48, in __get__
    res = instance.__dict__[self.name] = self.func(instance)
  File "/usr/local/lib/python3.6/dist-packages/django/urls/resolvers.py", line 589, in url_patterns
    patterns = getattr(self.urlconf_module, "urlpatterns", self.urlconf_module)
  File "/usr/local/lib/python3.6/dist-packages/django/utils/functional.py", line 48, in __get__
    res = instance.__dict__[self.name] = self.func(instance)
  File "/usr/local/lib/python3.6/dist-packages/django/urls/resolvers.py", line 582, in urlconf_module
    return import_module(self.urlconf_name)
  File "/usr/lib/python3.6/importlib/__init__.py", line 126, in import_module
    return _bootstrap._gcd_import(name[level:], package, level)
  File "<frozen importlib._bootstrap>", line 994, in _gcd_import
  File "<frozen importlib._bootstrap>", line 971, in _find_and_load
  File "<frozen importlib._bootstrap>", line 955, in _find_and_load_unlocked
  File "<frozen importlib._bootstrap>", line 665, in _load_unlocked
  File "<frozen importlib._bootstrap_external>", line 678, in exec_module
  File "<frozen importlib._bootstrap>", line 219, in _call_with_frames_removed
  File "/etc/django/receivefiles/receivefiles/urls.py", line 19, in <module>
    from . import views
  File "/etc/django/receivefiles/receivefiles/views.py", line 137
    return render(request, 'back.html', context=)
                                                ^
SyntaxError: invalid syntax

Performing system checks...

Performing system checks...

System check identified no issues (0 silenced).

You have 18 unapplied migration(s). Your project may not work properly until you apply the migrations for app(s): admin, auth, contenttypes, sessions.
Run 'python manage.py migrate' to apply them.
November 27, 2020 - 01:39:10
Django version 3.1.3, using settings 'receivefiles.settings'
Starting development server at http://0.0.0.0:2580/
Quit the server with CONTROL-C.
Performing system checks...

System check identified no issues (0 silenced).

You have 18 unapplied migration(s). Your project may not work properly until you apply the migrations for app(s): admin, auth, contenttypes, sessions.
Run 'python manage.py migrate' to apply them.
November 27, 2020 - 01:40:33
Django version 3.1.3, using settings 'receivefiles.settings'
Starting development server at http://0.0.0.0:2580/
Quit the server with CONTROL-C.
Performing system checks...

System check identified no issues (0 silenced).

You have 18 unapplied migration(s). Your project may not work properly until you apply the migrations for app(s): admin, auth, contenttypes, sessions.
Run 'python manage.py migrate' to apply them.
November 27, 2020 - 01:40:56
Django version 3.1.3, using settings 'receivefiles.settings'
Starting development server at http://0.0.0.0:2580/
Quit the server with CONTROL-C.
Performing system checks...

System check identified no issues (0 silenced).

You have 18 unapplied migration(s). Your project may not work properly until you apply the migrations for app(s): admin, auth, contenttypes, sessions.
Run 'python manage.py migrate' to apply them.
November 27, 2020 - 01:41:58
Django version 3.1.3, using settings 'receivefiles.settings'
Starting development server at http://0.0.0.0:2580/
Quit the server with CONTROL-C.
Performing system checks...

System check identified no issues (0 silenced).

You have 18 unapplied migration(s). Your project may not work properly until you apply the migrations for app(s): admin, auth, contenttypes, sessions.
Run 'python manage.py migrate' to apply them.
November 27, 2020 - 01:42:04
Django version 3.1.3, using settings 'receivefiles.settings'
Starting development server at http://0.0.0.0:2580/
Quit the server with CONTROL-C.
Performing system checks...

System check identified no issues (0 silenced).

You have 18 unapplied migration(s). Your project may not work properly until you apply the migrations for app(s): admin, auth, contenttypes, sessions.
Run 'python manage.py migrate' to apply them.
November 27, 2020 - 01:43:07
Django version 3.1.3, using settings 'receivefiles.settings'
Starting development server at http://0.0.0.0:2580/
Quit the server with CONTROL-C.
Performing system checks...

System check identified no issues (0 silenced).

You have 18 unapplied migration(s). Your project may not work properly until you apply the migrations for app(s): admin, auth, contenttypes, sessions.
Run 'python manage.py migrate' to apply them.
November 27, 2020 - 01:43:10
Django version 3.1.3, using settings 'receivefiles.settings'
Starting development server at http://0.0.0.0:2580/
Quit the server with CONTROL-C.
Performing system checks...

System check identified no issues (0 silenced).

You have 18 unapplied migration(s). Your project may not work properly until you apply the migrations for app(s): admin, auth, contenttypes, sessions.
Run 'python manage.py migrate' to apply them.
November 27, 2020 - 01:43:13
Django version 3.1.3, using settings 'receivefiles.settings'
Starting development server at http://0.0.0.0:2580/
Quit the server with CONTROL-C.
Performing system checks...

System check identified no issues (0 silenced).

You have 18 unapplied migration(s). Your project may not work properly until you apply the migrations for app(s): admin, auth, contenttypes, sessions.
Run 'python manage.py migrate' to apply them.
November 27, 2020 - 01:43:42
Django version 3.1.3, using settings 'receivefiles.settings'
Starting development server at http://0.0.0.0:2580/
Quit the server with CONTROL-C.
Performing system checks...

System check identified no issues (0 silenced).

You have 18 unapplied migration(s). Your project may not work properly until you apply the migrations for app(s): admin, auth, contenttypes, sessions.
Run 'python manage.py migrate' to apply them.
November 27, 2020 - 01:44:18
Django version 3.1.3, using settings 'receivefiles.settings'
Starting development server at http://0.0.0.0:2580/
Quit the server with CONTROL-C.
Performing system checks...

System check identified no issues (0 silenced).

You have 18 unapplied migration(s). Your project may not work properly until you apply the migrations for app(s): admin, auth, contenttypes, sessions.
Run 'python manage.py migrate' to apply them.
November 27, 2020 - 01:45:24
Django version 3.1.3, using settings 'receivefiles.settings'
Starting development server at http://0.0.0.0:2580/
Quit the server with CONTROL-C.
[27/Nov/2020 01:47:10] "GET / HTTP/1.1" 200 844
[27/Nov/2020 01:47:10] "GET /favicon.ico HTTP/1.1" 500 4061
